Workbook

Sheet Guide & Setup
B2: ENGINEERING TOOL — NO DL
B3: Standalone properties. No VBA, DLLs, add-ins, external workbook links, or database calls are required.
B5: HOW TO USE THIS COPY
B6: Keep this file as .xlsx. Change the orange input cells and choose Ideal Gas or Peng-Robinson on each gas calculator. The original .xlsm is a separate file.
B7: Ideal Gas sets Z=1. Peng-Robinson calculates gas compressibility, density, enthalpy departure, heat capacities, and sound speed using ordinary worksheet formulas.
B8: All constants and coefficients are stored on gas properties. Property calculations contains the working equations; nothing is downloaded when inputs change.
B9: Relief Valve Calculator also retains Manual Z. Enter a positive compressibility value appropriate to the relieving conditions.
B10: Polytropic pipe flow: Data > What-If Analysis > Goal Seek. Set C37 to 0 by changing C9. Repeat after changing inputs; no workbook macro is involved.
B11: Gas Temp Rise in Pipe: compare 25 and 50 segments. Each node solves total enthalpy (h + velocity squared / 2) using nine bounded Newton evaluations; residual must be below 0.1 J/kg.
B13: SUPPORTED CONDITIONS AND LIMITS
B14: Gas range: 250-600 K, minimum 0.01 bar abs. AIR, NITROGEN, ARGON and HELIUM: 7000 psig. HYDROGEN: 10000 psig. Other gases retain 100 bar abs. Each sheet uses its entered atmospheric pressure to convert gauge limits to absolute.
B15: Gas screening: below 1.05 times critical temperature, pressure must be below half the estimated Wilson saturation pressure. This conservative screening is not a phase-equilibrium calculation.
... B45: Sources and coefficient provenance are recorded on gas properties. URLs are documentation only. The workbook contains static reference data, not live external connections.

Sheet Flow rate converter
B1: GAS FLOW RATE CONVERTER
B2: Convert mass flow and volumetric flow using actual, standard, or normal gas conditions, including humidity effects for Air
B3: Cells with an orange fill are inputs. Cells with a green fill are converted outputs. Relative humidity inputs apply only when Fluid Type is Air.
B4: =IF(UPPER(C9)="WATER","Water: existing constant-density conversion only",IF(AND(UPPER(C9)="AIR",OR(C15>0,F15>0),MAX(E12,E13)>1000000),"BLOCK: humid-air conversion above 10 bar is unsupported",IF('Property calculations'!AU4=0,'Property calculations'!AV4,IF('Property calculations'!AU5=0,'Property calculations'!AV5,'Property calculations'!AV4)))) -> Gas estimate within calculation range
B5: INPUTS
B6: Gauge Pressure | C6: 100 | D6: psig | E6: =C6*6894.757293168 -> 689475.73 | F6: Pa
B7: Mass Flow Rate | C7: 631.6 | D7: lbm/hr
B8: Temperature | C8: 70 | D8: F | E8: =+(C8-32)*5/9+273.15 -> 294.26111 | F8: K
B9: Fluid Type | C9: Argon
B10: Density Method | C10: Ideal Gas
B11: Ambient Pressure | C11: 12.2 | D11: psia | E11: =C11*6894.757293168 -> 84116.039 | F11: Pa
B12: Total Pressure | C12: =C6+C11 -> 112.2 | D12: psia | E12: =C12*6894.757293168 -> 773591.77 | F12: Pa
B13: Standard or Normal Pressure | C13: 14.7 | D13: psia | E13: =C13*6894.757293168 -> 101352.93 | F13: Pa
B14: Standard or Normal Temperature | C14: 70 | D14: F | E14: =(C14-32)*5/9+273.15 -> 294.26111 | F14: K
B15: Actual Relative Humidity | C15: 0 | D15: % RH | E15: Standard / Normal RH | F15: 0 | G15: % RH
B16: OUTPUTS
B17: Mass Flow Rate | C17: =$C$7/3600 -> 0.17544444 | D17: lb/s
B18: Mass Flow Rate | C18: =$C$7/60 -> 10.526667 | D18: lb/min
B19: Mass Flow Rate | C19: =$C$7 -> 631.6 | D19: lb/hr
B20: Mass Flow Rate | C20: =$C$7*0.45359237/3600 -> 0.079580261 | D20: kg/s
B21: Mass Flow Rate | C21: =$C$7*0.45359237/60 -> 4.7748157 | D21: kg/min
B22: Mass Flow Rate | C22: =$C$7*0.45359237 -> 286.48894 | D22: kg/hr
B23: Standard / Normal Volume Flow | C23: =IF(UPPER($C$9)="WATER","NA",$C$22/IF($C$10="Ideal Gas",$C$34,IF($C$10="Peng-Robinson",$C$33,NA()))) -> 173.1089 | D23: Nm³/hr
B24: Standard CFM | C24: =IF(UPPER($C$9)="WATER","NA",($C$19/(IF($C$10="Ideal Gas",$C$34,IF($C$10="Peng-Robinson",$C$33,NA()))*0.062428))/60) -> 101.88799 | D24: SCFM
B25: Actual Volume Flow | C25: =($C$19/($C$32*0.062428))/60 -> 13.348961 | D25: ACFM
B27: FLUID PROPERTIES
B28: Molecular Weight | C28: =VLOOKUP($C$9,'gas properties'!$B$3:$E$13,2,FALSE) -> 39.948 | D28: g/mol
C29: IDEAL GAS | E29: SELECTED METHOD | G29: DIFFERENCE
B30: Density | C30: =IF(UPPER($C$9)="WATER",999.8,IF(UPPER($C$9)="AIR",(($E$12-$C$35)*0.02896546+$C$35*0.01801528)/($C$31*$E$8),(1/1000)*$E$12*C28/(C31*$E$8))) -> 12.631764 | D30: kg/m^3 | E30: =IF(UPPER(C9)="WATER",999.8,IF(AND(UPPER(C9)="AIR",C15>0),IF(E12>1000000,NA(),C30),'Property calculations'!BC4)) -> 12.631061 | F30: kg/m^3 | G30: =IF(UPPER($C$9)="WATER","NA",(C30-E30)/E30) -> 5.5643252e-05
B31: R | C31: 8.314 | D31: Pa*m^3/(mol*K)
B32: Density Used | C32: =IF(UPPER(C9)="WATER",999.8,IF('Property calculations'!AU4<>1,NA(),IF(AND(UPPER(C9)="AIR",C15>0),IF(E12>1000000,NA(),C30),IF(C10="Ideal Gas",C30,E30)))) -> 12.631764 | D32: kg/m^3
B33: Reference density (selected) | C33: =IF(UPPER(C9)="WATER","NA",IF(AND(UPPER(C9)="AIR",F15>0),IF(E13>1000000,NA(),C34),'Property calculations'!BC5)) -> 1.6548716 | D33: kg/m^3
B34: Reference density (ideal) | C34: =IF(AND(UPPER(C9)="AIR",F15>0,E13>1000000),NA(),IF(UPPER(C9)="WATER","NA",IF('Property calculations'!AU5=1,IF(UPPER($C$9)="WATER","NA",IF(UPPER($C$9)="AIR",(($E$13-$E$35)*0.02896546+$E$35*0.01801528)/($C$31*$E$14),(1/1000)*$E$13*$C$28/($C$31*$E$14))),NA()))) -> 1.6549637 | D34: kg/m^3
B35: Water Vapor Partial Pressure (Air only) | C35: =IF(UPPER($C$9)="AIR",MIN($E$12*0.999999,MAX(0,$C$15)*IF((($C$8-32)*5/9)>=0,EXP(34.494-4924.99/((($C$8-32)*5/9)+237.1))/(((($C$8-32)*5/9)+105)^1.57),EXP(43.494-6545.8/((($C$8-32)*5/9)+278))/(((($C$8-32)*5/9)+868)^2))),0) -> 0 | D35: Pa actual | E35: =IF(UPPER($C$9)="AIR",MIN($E$13*0.999999,MAX(0,$F$15)*IF((($C$14-32)*5/9)>=0,EXP(34.494-4924.99/((($C$14-32)*5/9)+237.1))/(((($C$14-32)*5/9)+105)^1.57),EXP(43.494-6545.8/((($C$14-32)*5/9)+278))/(((($C$14-32)*5/9)+868)^2))),0) -> 0 | F35: Pa std/norm
B36: CALCULATION LOGIC & THEORY
B37: This section explains the equations, conversions, and exact worksheet cells used. The converter starts with mass flow in C7 and uses density to calculate actual or reference-condition volumetric flow.
B39: TOPIC | C39: CALCULATION CELL(S) | D39: LOGIC / THEORY / CONVERSION
B40: Pressure conversion | C40: E6, E11:E13 | D40: Pressure in psi is converted to pascals using P (Pa) = P (psi) × 6,895. E6 converts gauge pressure, E11 converts ambient absolute pressure, E12 converts total absolute pressure, and E13 converts the selected standard/normal pressure.
B41: Absolute pressure | C41: C12, E12 | D41: C12 calculates total absolute pressure as gauge pressure C6 + ambient pressure C11. Gas density equations require absolute pressure, so E12—not gauge pressure E6—is used for the actual-condition density calculations.
B42: Temperature conversion | C42: E8, E14 | D42: Temperature is converted from °F to K using T (K) = (T (°F) − 32) × 5/9 + 273.15. E8 is actual gas temperature; E14 is the standard/normal reference temperature. C15 and F15 are the corresponding relative-humidity inputs used only for Air.
...

Sheet polytropic pipe flow
B1: POLYTROPIC GAS PIPE FLOW CALCULATOR
B2: Compressible-gas pipe-flow model with polytropic expansion, friction, fittings, and choking checks
B3: Cells with an orange fill are inputs. Results are summarized below the input block; supporting calculations follow. | D3: Orange cells are inputs. Select Ideal Gas or Peng-Robinson; use Goal Seek C37 = 0 by changing C9.
B4: =IF(UPPER(C11)="WATER","Water: existing pipe model assumptions remain; not a flashing-flow solver",'Property calculations'!AV6) -> Gas estimate within calculation range
C5: INPUTS
B6: STATUS | C6: =IF(AND(UPPER(C11)<>"WATER",'Property calculations'!AU6=0),'Property calculations'!AV6,IF(C7<=C8,"CHECK: Pin must exceed Pout",IF(C35<=0,"CHECK: elevation exceeds pressure head",IF(H82<1,"CHECK: Eq. 34 valid for K >= 1",IF(C60>C62,"CHOKED: using choked pressure drop","SUBSONIC: using actual pressure drop"))))) -> SUBSONIC: using actual pressure drop | M6: Item | N6: Rigid PVC/HDPE | O6: Glass-reinforced plastic / fiber-reinforced plastic | P6: Commercial Steel | Q6: Spiral Weld Steel
B7: Pin | C7: 25 | D7: psig | E7: =(C7+$C$19)*6894.757293168 -> 273721.86 | F7: Pa abs | M7: 45° threaded elbow, r/D=1 | N7: 20 | O7: 18 | P7: 16 | Q7: 14
B8: Pout | C8: 24.999481 | D8: psig | E8: =(C8+$C$19)*6894.757293168 -> 273718.29 | F8: Pa abs | M8: 90° threaded elbow, r/D=1 | N8: 37 | O8: 34 | P8: 30 | Q8: 26
B9: Mass flow guess (Goal Seek) | C9: 15 | D9: lbm/hr | M9: 90° welded elbow, r/D=1.5 | N9: 17 | O9: 15 | P9: 13 | Q9: 12
B10: INLET TEMP | C10: 70 | D10: F | E10: =+(C10-32)*5/9+273.15 -> 294.26111 | F10: K | M10: Ball valve, full bore | N10: 3.3 | O10: 3 | P10: 2.6 | Q10: 2.3
B11: Fluid Type | C11: ARGON | M11: Swing check valve | N11: 120 | O11: 110 | P11: 95 | Q11: 85
B12: ID | C12: 2.065 | D12: in | M12: Globe valve, full open | N12: 400 | O12: 370 | P12: 320 | Q12: 280
B13: Property source | C13: Peng-Robinson | M13: Threaded tee, branch | N13: 75 | O13: 68 | P13: 60 | Q13: 53
B14: Flow model | C14: Polytropic (Eq. 25) | M14: Threaded tee, straight run | N14: 25 | O14: 23 | P14: 20 | Q14: 18
B15: Polytropic index used (c) | C15: =IF(C14="Isothermal",1,IF(C14="Isentropic",C49,C58)) -> 1.0000004
B16: pipe roughness | C16: 0.0005 | D16: in
B17: pipe length | C17: 100 | D17: ft
B18: Elevation rise (+) | C18: 0 | D18: ft
B19: Atmospheric pressure | C19: 14.7 | D19: psia
B20: Minor loss material basis | C20: Commercial Steel | D20: commercial-steel fitting equivalent-length assumptions
B22: RESULTS
B23: Status | C23: =C6 -> SUBSONIC: using actual pressure drop
B24: Mass flow rate | C24: =C9/60 -> 0.25 | D24: lb/min
B25: Mass flow rate | C25: =C24*27.2155 -> 6.803875 | D25: kg/hr
B26: Mass flow rate | C26: =C25/60 -> 0.11339792 | D26: kg/min
B27: SCFM | C27: =C28*C51/C61 -> 2.246778 | D27: ft^3/min
B28: ACFM | C28: =(C9/(C51*0.062428))/60 -> 0.89366403 | D28: ft^3/min
B29: Mass flow rate | C29: =C9/3600 -> 0.0041666667 | D29: lb/s
B30: Mass flow rate | C30: =C25/3600 -> 0.0018899653 | D30: kg/s
B31: P2 choked | C31: =E7*(1-C62)/6894.757293168-$C$19 -> -10.329081 | D31: psig
B32: Pipe gas velocity | C32: =C50 -> 0.19514883 | D32: m/s
B33: Mach number | C33: =C54 -> 0.00061068915 | D33: [-]
B34: GOAL SEEK / SOLVER
B35: Available pressure term | C35: =E7*C63-C18*0.3048*C51*C56 -> 3.5781067
B36: Calculated loss term | C36: =C51*C56*F82/(C59^2) -> 3.3093547
B37: Residual (target 0) | C37: =C35-C36 -> 0.26875196
B40: FLUID PROPERTIES
B41: Molecular Weight | C41: =INDEX('gas properties'!$C$4:$C$13,MATCH(UPPER(C11),'gas properties'!$B$4:$B$13,0)) -> 39.948 | D41: g/mol
C42: IDEAL / LEGACY | E42: SELECTED METHOD | G42: DIFFERENCE
B43: Density | C43: =IF(C11="WATER",999.8,(1/1000)*E7*C41/(C45*E10)) -> 4.4695278 | D43: kg/m^3 | E43: =IF(UPPER(C11)="WATER",999.8,'Property calculations'!BC6) -> 4.4811173 | F43: kg/m^3 | G43: =IF(UPPER(C11)="WATER","NA",(C43-E43)/E43) -> -0.0025862959
...

Sheet Gas Temp Rise in Pipe
A1: GAS TEMPERATURE RISE IN HORIZONTAL PIPE
A2: Steady-state 1-D gas model with selectable properties, Darcy pressure loss and wall heat transfer
A3: Cells with an orange fill are inputs. Isothermal = constant temperature at the outside pipe/insulation surface; adiabatic ignores thermal-resistance inputs.
A4: ='Property calculations'!AV13&". Heat transfer uses low-pressure transport estimates." -> Gas estimate within calculation range. Heat transfer uses low-pressure transport estimates.
A5: INPUTS | E5: RESULTS
A6: Gas | C6: ARGON | E6: Status | G6: =IF('Property calculations'!AU13=0,'Property calculations'!AV13,IF(AND(N38>10000000,(IFERROR(IF(OR($C$7<=0,$C$9<0,$C$10<=0,$C$11<=0,$C$12<=0,$C$13<=$C$12,$C$14<0,$C$19<=0,AND($C$17="Insulated",OR($C$18<=0,$C$20<=0)),$C$21<5,$C$21>50,MOD($C$21,1)<>0),"CHECK INPUTS",IF(COUNTIF($AM$38:$AM$88,0)>0,"CHECK GAS RANGE",IF(MIN($N$38:$N$88)<=1000,"CHECK PRESSURE FLOOR",IF(MAX($T$38:$T$88)>=1,"CHECK CHOKING",IF(MAX($T$38:$T$88)>0.3,"HIGH MACH; REVIEW","OK - GAS ESTIMATE"))))),"CHECK RANGE / CONVERGENCE"))="OK - GAS ESTIMATE"),"WARNING: HIGH PRESSURE",IFERROR(IF(OR($C$7<=0,$C$9<0,$C$10<=0,$C$11<=0,$C$12<=0,$C$13<=$C$12,$C$14<0,$C$19<=0,AND($C$17="Insulated",OR($C$18<=0,$C$20<=0)),$C$21<5,$C$21>50,MOD($C$21,1)<>0),"CHECK INPUTS",IF(COUNTIF($AM$38:$AM$88,0)>0,"CHECK GAS RANGE",IF(MIN($N$38:$N$88)<=1000,"CHECK PRESSURE FLOOR",IF(MAX($T$38:$T$88)>=1,"CHECK CHOKING",IF(MAX($T$38:$T$88)>0.3,"HIGH MACH; REVIEW","OK - GAS ESTIMATE"))))),"CHECK RANGE / CONVERGENCE"))) -> OK - GAS ESTIMATE
A7: Flow rate | C7: 2 | D7: SCFM | E7: Outlet gas temperature | G7: =INDEX($L$38:$L$88,$C$21+1) -> 199.17606 | H7: °F
A8: Inlet gas temperature | C8: 5 | D8: °F | E8: Temperature change | G8: =$G$7-$C$8 -> 194.17606 | H8: °F
A9: Inlet gauge pressure | C9: 100 | D9: psig | E9: Outlet gauge pressure | G9: =INDEX($M$38:$M$88,$C$21+1) -> 99.999914 | H9: psig
A10: Atmospheric pressure | C10: 14.7 | D10: psia | E10: Pressure drop | G10: =$C$9-$G$9 -> 8.5775296e-05 | H10: psi
A11: Pipe length | C11: 100 | D11: ft | E11: Mass flow | G11: =$C$28*3600/0.45359237 -> 12.649189 | H11: lb/hr
A12: Pipe inner diameter | C12: 2.067 | D12: in | E12: Mass flow | G12: =$C$28 -> 0.001593771 | H12: kg/s
A13: Pipe outer diameter | C13: 2.375 | D13: in | E13: Heat transferred to gas | G13: =SUM($AA$38:$AA$88)/0.2930710702 -> 311.12994 | H13: Btu/hr
A14: Pipe roughness | C14: 0.0018 | D14: in | E14: Mean gas-side h | G14: =IFERROR(AVERAGEIF($Y$38:$Y$88,">0")/5.678263337,0) -> 0.24460569 | H14: Btu/(hr·ft²·°F)
A15: Boundary condition | C15: Isothermal | E15: Overall conductance (UA) | G15: =SUM($Z$38:$Z$88)/0.2930710702 -> 15.700682 | H15: Btu/(hr·°F)
A16: Boundary temperature | C16: 200 | D16: °F | E16: Maximum Mach number | G16: =MAX($T$38:$T$88) -> 0.00019806894 | H16: [-]
A17: Insulation | C17: Insulated | E17: Inlet velocity | G17: =$S$38*3.280839895 -> 0.16208281 | H17: ft/s
A18: Insulation thickness | C18: 1 | D18: in | E18: Outlet velocity | G18: =INDEX($S$38:$S$88,$C$21+1)*3.280839895 -> 0.23206389 | H18: ft/s
A19: Pipe thermal conductivity | C19: 26 | D19: Btu/(hr·ft·°F) | E19: Residence time | G19: =SUM($AH$38:$AH$88) -> 460.64035 | H19: s
A20: Insulation thermal conductivity | C20: 0.025 | D20: Btu/(hr·ft·°F) | E20: Pressure method | G20: Segmented Darcy-Weisbach
A21: Calculation segments | C21: 50 | D21: 5 to 50 | E21: Thermal method | G21: =IF($C$15="Adiabatic","Adiabatic total-enthalpy balance","Isothermal outer-surface heat transfer") -> Isothermal outer-surface heat transfer
A22: Property method | C22: Peng-Robinson | E22: Property method used | G22: =C22 -> Peng-Robinson
A24: CALCULATION DETAILS | E24: PROFILE SNAPSHOT
A25: Molecular weight | C25: =VLOOKUP(C6,'gas properties'!$B$4:$E$13,2,FALSE) -> 39.948 | D25: g/mol | E25: Point | F25: Distance (ft) | G25: Gas temp (°F) | H25: Pressure (psig)
A26: Isentropic coefficient (k) | C26: ='Property calculations'!BI13 -> 1.7045954 | D26: [-] | E26: Inlet | F26: 0 | G26: =$C$8 -> 5 | H26: =$C$9 -> 100
A27: Local property method | C27: =C22 -> Peng-Robinson | E27: Midpoint | F27: =$C$11*ROUND($C$21/2,0)/$C$21 -> 50 | G27: =INDEX($L$38:$L$88,ROUND($C$21/2,0)+1) -> 186.14205 | H27: =INDEX($M$38:$M$88,ROUND($C$21/2,0)+1) -> 99.999961
A28: Mass flow | C28: =IF($D$7="lb/hr",$C$7*0.45359237/3600,IF($D$7="kg/hr",$C$7/3600,IF($D$7="ACFM",$C$7*0.028316846592/60*$C$32,$C$7*0.028316846592/60*'Property calculations'!BC12))) -> 0.001593771 | D28: kg/s | E28: Outlet | F28: =$C$11 -> 100 | G28: =$G$7 -> 199.17606 | H28: =$G$9 -> 99.999914
A29: Flow area | C29: =PI()/4*($C$12*0.0254)^2 -> 0.0021649021 | D29: m²
A30: Segment length | C30: =$C$11*0.3048/$C$21 -> 0.6096 | D30: m | E30: MODEL NOTES
A31: Inlet Cp | C31: ='Property calculations'!BE13 -> 535.18624 | D31: J/(kg·K) | E31: Adiabatic: no wall heat transfer; insulation and boundary-temperature inputs are ignored.
A32: Inlet density | C32: ='Property calculations'!BC13 -> 14.901697 | D32: kg/m³ | E32: Properties: 250–600 K, gas states only.
A33: Inlet viscosity | C33: ='Property calculations'!BG13 -> 2.0470781e-05 | D33: Pa·s | E33: Transport uses low-pressure correlations.
A34: Inlet conductivity | C34: ='Property calculations'!BH13 -> 0.015817311 | D34: W/(m·K) | E34: Review segment count and Mach number.
A35: Inlet Reynolds number | C35: =4*$C$28/(PI()*($C$12*0.0254)*$C$33) -> 1888.1106 | D35: [-] | E35: See Guide & Setup for model limits.
J37: Node | K37: Distance_ft | L37: Gas_T_F | M37: Pressure_psig | N37: Pressure_Pa | O37: Temp_K | P37: Density | Q37: Viscosity | R37: Conductivity | S37: Velocity | T37: Mach | U37: Reynolds | V37: Prandtl | W37: Darcy_f | X37: Nusselt | Y37: h_i | Z37: UA_seg | AA37: Heat_W | AB37: q_per_mass | AC37: dP_Pa | AD37: P_next | AE37: T_no_kin | AF37: rho_prov | AG37: V_next | AH37: Residence_s | AI37: Boundary_T_F | AJ37: Cp_J_kgK | AK37: Enthalpy_J_kg | AL37: Sound_m_s | AM37: Gas screen (1 = within envelope)
J38: 0 | K38: 0 | L38: =IF($J38<=$C$21,($O38-273.15)*9/5+32,"") -> 5 | M38: =IF($J38<=$C$21,$N38/6894.757293168-$C$10,"") -> 100 | N38: =($C$9+$C$10)*6894.757293168 -> 790828.66 | O38: =($C$8-32)*5/9+273.15 -> 258.15 | P38: =IF($J38<=$C$21,'Property calculations'!BC13,"") -> 14.901697 | Q38: =IF($J38<=$C$21,'Property calculations'!BG13,"") -> 2.0470781e-05 | R38: =IF($J38<=$C$21,'Property calculations'!BH13,"") -> 0.015817311 | S38: =IF($J38<=$C$21,$C$28/($P38*$C$29),"") -> 0.049402842 | T38: =IF($J38<=$C$21,$S38/$AL38,"") -> 0.00016525578 | U38: =IF($J38<=$C$21,$P38*$S38*($C$12*0.0254)/$Q38,"") -> 1888.1106 | V38: =IF($J38<=$C$21,$AJ38*$Q38/$R38,"") -> 0.6926386 | W38: =IF($J38<=$C$21,IF($U38<2300,64/$U38,0.25/(LOG10(($C$14/$C$12)/3.7+5.74/$U38^0.9)^2)),"") -> 0.033896319 | X38: =IF($J38<=$C$21,IF($U38<2300,3.66,IF($U38>=10000,0.023*$U38^0.8*$V38^IF((($C$16-32)*5/9+273.15)>$O38,0.4,0.3),3.66+($U38-2300)/(10000-2300)*(0.023*10000^0.8*$V38^IF((($C$16-32)*5/9+273.15)>$O38,0.4,0.3)-3.66))),"") -> 3.66 | Y38: =IF($J38<=$C$21,$X38*$R38/($C$12*0.0254),"") -> 1.1026547 | Z38: =IF(OR($J38>=$C$21,$C$15="Adiabatic"),0,1/(1/($Y38*2*PI()*($C$12*0.0254/2)*$C$30)+LN(($C$13*0.0254/2)/($C$12*0.0254/2))/(2*PI()*($C$19*1.730734666)*$C$30)+IF($C$17="Insulated",LN((($C$13*0.0254/2)+$C$18*0.0254)/($C$13*0.0254/2))/(2*PI()*($C$20*1.730734666)*$C$30),0))) -> 0.078698565 | AA38: =IF($J38>=$C$21,0,IF($C$15="Adiabatic",0,$C$28*$AJ38*((($C$16-32)*5/9+273.15)-$O38)*(1-EXP(-$Z38/($C$28*$AJ38))))) -> 8.1441902 | AB38: =IF($J38>=$C$21,0,$AA38/$C$28) -> 5110.0129 | AC38: =IF($J38>=$C$21,0,$W38*($C$30/($C$12*0.0254))*($P38*$S38^2/2)) -> 0.0071570309 | AD38: =IF($J38>=$C$21,$N38,MAX(1000,$N38-$AC38)) -> 790828.65 | AE38: =IF($J38>=$C$21,$O38,$O39) -> 267.70888 | AF38: =IF($J38>=$C$21,$P38,$P39) -> 14.347911 | AG38: =IF($J38>=$C$21,$S38,$C$28/($AF38*$C$29)) -> 0.051309642 | AH38: =IF($J38>=$C$21,0,$C$30/AVERAGE($S38,$AG38)) -> 12.105748 | AI38: =IF($J38<=$C$21,IF($C$15="Adiabatic","",$C$16),"") -> 200 | AJ38: =IF($J38<=$C$21,'Property calculations'!BE13,"") -> 535.18624 | AK38: =IF($J38<=$C$21,'Property calculations'!BD13,"") -> -23133.709 | AL38: =IF($J38<=$C$21,'Property calculations'!BF13,"") -> 298.94773 | AM38: =IF($J38<=$C$21,'Property calculations'!AU13,"") -> 1
J39: =J38+1 -> 1 | K39: =IF($J39<=$C$21,$J39*$C$11/$C$21,"") -> 2 | L39: =IF($J39<=$C$21,($O39-273.15)*9/5+32,"") -> 22.205991 | M39: =IF($J39<=$C$21,$N39/6894.757293168-$C$10,"") -> 99.999999 | N39: =IF($J39<=$C$21,$AD38,"") -> 790828.65 | O39: =IF(J39<=$C$21,IF(AND('Property calculations'!AU22=1,ABS('Property calculations'!BA22)<0.1),'Property calculations'!C22,NA()),"") -> 267.70888 | P39: =IF($J39<=$C$21,'Property calculations'!BC22,"") -> 14.347911 | Q39: =IF($J39<=$C$21,'Property calculations'!BG22,"") -> 2.0998481e-05 | R39: =IF($J39<=$C$21,'Property calculations'!BH22,"") -> 0.016284153 | S39: =IF($J39<=$C$21,$C$28/($P39*$C$29),"") -> 0.051309642 | T39: =IF($J39<=$C$21,$S39/$AL39,"") -> 0.0001684487 | U39: =IF($J39<=$C$21,$P39*$S39*($C$12*0.0254)/$Q39,"") -> 1840.6617 | V39: =IF($J39<=$C$21,$AJ39*$Q39/$R39,"") -> 0.68859899 | W39: =IF($J39<=$C$21,IF($U39<2300,64/$U39,0.25/(LOG10(($C$14/$C$12)/3.7+5.74/$U39^0.9)^2)),"") -> 0.034770105 | X39: =IF($J39<=$C$21,IF($U39<2300,3.66,IF($U39>=10000,0.023*$U39^0.8*$V39^IF((($C$16-32)*5/9+273.15)>$O39,0.4,0.3),3.66+($U39-2300)/(10000-2300)*(0.023*10000^0.8*$V39^IF((($C$16-32)*5/9+273.15)>$O39,0.4,0.3)-3.66))),"") -> 3.66 | Y39: =IF($J39<=$C$21,$X39*$R39/($C$12*0.0254),"") -> 1.1351992 | Z39: =IF(OR($J39>=$C$21,$C$15="Adiabatic"),0,1/(1/($Y39*2*PI()*($C$12*0.0254/2)*$C$30)+LN(($C$13*0.0254/2)/($C$12*0.0254/2))/(2*PI()*($C$19*1.730734666)*$C$30)+IF($C$17="Insulated",LN((($C$13*0.0254/2)+$C$18*0.0254)/($C$13*0.0254/2))/(2*PI()*($C$20*1.730734666)*$C$30),0))) -> 0.080333344 | AA39: =IF($J39>=$C$21,0,IF($C$15="Adiabatic",0,$C$28*$AJ39*((($C$16-32)*5/9+273.15)-$O39)*(1-EXP(-$Z39/($C$28*$AJ39))))) -> 7.5719046 | AB39: =IF($J39>=$C$21,0,$AA39/$C$28) -> 4750.9364 | AC39: =IF($J39>=$C$21,0,$W39*($C$30/($C$12*0.0254))*($P39*$S39^2/2)) -> 0.0076248869 | AD39: =IF($J39>=$C$21,$N39,MAX(1000,$N39-$AC39)) -> 790828.65 | AE39: =IF($J39>=$C$21,$O39,$O40) -> 276.61405 | AF39: =IF($J39>=$C$21,$P39,$P40) -> 13.868833 | AG39: =IF($J39>=$C$21,$S39,$C$28/($AF39*$C$29)) -> 0.053082054 | AH39: =IF($J39>=$C$21,0,$C$30/AVERAGE($S39,$AG39)) -> 11.67909 | AI39: =IF($J39<=$C$21,IF($C$15="Adiabatic","",$C$16),"") -> 200 | AJ39: =IF($J39<=$C$21,'Property calculations'!BE22,"") -> 534.003 | AK39: =IF($J39<=$C$21,'Property calculations'!BD22,"") -> -18023.697 | AL39: =IF($J39<=$C$21,'Property calculations'!BF22,"") -> 304.601 | AM39: =IF($J39<=$C$21,'Property calculations'!AU22,"") -> 1
J40: =J39+1 -> 2 | K40: =IF($J40<=$C$21,$J40*$C$11/$C$21,"") -> 4 | L40: =IF($J40<=$C$21,($O40-273.15)*9/5+32,"") -> 38.235296 | M40: =IF($J40<=$C$21,$N40/6894.757293168-$C$10,"") -> 99.999998 | N40: =IF($J40<=$C$21,$AD39,"") -> 790828.65 | O40: =IF(J40<=$C$21,IF(AND('Property calculations'!AU31=1,ABS('Property calculations'!BA31)<0.1),'Property calculations'!C31,NA()),"") -> 276.61405 | P40: =IF($J40<=$C$21,'Property calculations'!BC31,"") -> 13.868833 | Q40: =IF($J40<=$C$21,'Property calculations'!BG31,"") -> 2.1485026e-05 | R40: =IF($J40<=$C$21,'Property calculations'!BH31,"") -> 0.016716076 | S40: =IF($J40<=$C$21,$C$28/($P40*$C$29),"") -> 0.053082054 | T40: =IF($J40<=$C$21,$S40/$AL40,"") -> 0.00017136343 | U40: =IF($J40<=$C$21,$P40*$S40*($C$12*0.0254)/$Q40,"") -> 1798.9784 | V40: =IF($J40<=$C$21,$AJ40*$Q40/$R40,"") -> 0.68508761 | W40: =IF($J40<=$C$21,IF($U40<2300,64/$U40,0.25/(LOG10(($C$14/$C$12)/3.7+5.74/$U40^0.9)^2)),"") -> 0.035575746 | X40: =IF($J40<=$C$21,IF($U40<2300,3.66,IF($U40>=10000,0.023*$U40^0.8*$V40^IF((($C$16-32)*5/9+273.15)>$O40,0.4,0.3),3.66+($U40-2300)/(10000-2300)*(0.023*10000^0.8*$V40^IF((($C$16-32)*5/9+273.15)>$O40,0.4,0.3)-3.66))),"") -> 3.66 | Y40: =IF($J40<=$C$21,$X40*$R40/($C$12*0.0254),"") -> 1.1653094 | Z40: =IF(OR($J40>=$C$21,$C$15="Adiabatic"),0,1/(1/($Y40*2*PI()*($C$12*0.0254/2)*$C$30)+LN(($C$13*0.0254/2)/($C$12*0.0254/2))/(2*PI()*($C$19*1.730734666)*$C$30)+IF($C$17="Insulated",LN((($C$13*0.0254/2)+$C$18*0.0254)/($C$13*0.0254/2))/(2*PI()*($C$20*1.730734666)*$C$30),0))) -> 0.08182131 | AA40: =IF($J40>=$C$21,0,IF($C$15="Adiabatic",0,$C$28*$AJ40*((($C$16-32)*5/9+273.15)-$O40)*(1-EXP(-$Z40/($C$28*$AJ40))))) -> 7.0102082 | AB40: =IF($J40>=$C$21,0,$AA40/$C$28) -> 4398.5041 | AC40: =IF($J40>=$C$21,0,$W40*($C$30/($C$12*0.0254))*($P40*$S40^2/2)) -> 0.0080710522 | AD40: =IF($J40>=$C$21,$N40,MAX(1000,$N40-$AC40)) -> 790828.64 | AE40: =IF($J40>=$C$21,$O40,$O41) -> 284.87254 | AF40: =IF($J40>=$C$21,$P40,$P41) -> 13.453036 | AG40: =IF($J40>=$C$21,$S40,$C$28/($AF40*$C$29)) -> 0.054722677 | AH40: =IF($J40>=$C$21,0,$C$30/AVERAGE($S40,$AG40)) -> 11.309337 | AI40: =IF($J40<=$C$21,IF($C$15="Adiabatic","",$C$16),"") -> 200 | AJ40: =IF($J40<=$C$21,'Property calculations'!BE31,"") -> 533.02131 | AK40: =IF($J40<=$C$21,'Property calculations'!BD31,"") -> -13272.76 | AL40: =IF($J40<=$C$21,'Property calculations'!BF31,"") -> 309.76302 | AM40: =IF($J40<=$C$21,'Property calculations'!AU31,"") -> 1
J41: =J40+1 -> 3 | K41: =IF($J41<=$C$21,$J41*$C$11/$C$21,"") -> 6 | L41: =IF($J41<=$C$21,($O41-273.15)*9/5+32,"") -> 53.100568 | M41: =IF($J41<=$C$21,$N41/6894.757293168-$C$10,"") -> 99.999997 | N41: =IF($J41<=$C$21,$AD40,"") -> 790828.64 | O41: =IF(J41<=$C$21,IF(AND('Property calculations'!AU40=1,ABS('Property calculations'!BA40)<0.1),'Property calculations'!C40,NA()),"") -> 284.87254 | P41: =IF($J41<=$C$21,'Property calculations'!BC40,"") -> 13.453036 | Q41: =IF($J41<=$C$21,'Property calculations'!BG40,"") -> 2.1932055e-05 | R41: =IF($J41<=$C$21,'Property calculations'!BH40,"") -> 0.017114154 | S41: =IF($J41<=$C$21,$C$28/($P41*$C$29),"") -> 0.054722677 | T41: =IF($J41<=$C$21,$S41/$AL41,"") -> 0.00017401807 | U41: =IF($J41<=$C$21,$P41*$S41*($C$12*0.0254)/$Q41,"") -> 1762.3108 | V41: =IF($J41<=$C$21,$AJ41*$Q41/$R41,"") -> 0.68202337 | W41: =IF($J41<=$C$21,IF($U41<2300,64/$U41,0.25/(LOG10(($C$14/$C$12)/3.7+5.74/$U41^0.9)^2)),"") -> 0.036315954 | X41: =IF($J41<=$C$21,IF($U41<2300,3.66,IF($U41>=10000,0.023*$U41^0.8*$V41^IF((($C$16-32)*5/9+273.15)>$O41,0.4,0.3),3.66+($U41-2300)/(10000-2300)*(0.023*10000^0.8*$V41^IF((($C$16-32)*5/9+273.15)>$O41,0.4,0.3)-3.66))),"") -> 3.66 | Y41: =IF($J41<=$C$21,$X41*$R41/($C$12*0.0254),"") -> 1.1930601 | Z41: =IF(OR($J41>=$C$21,$C$15="Adiabatic"),0,1/(1/($Y41*2*PI()*($C$12*0.0254/2)*$C$30)+LN(($C$13*0.0254/2)/($C$12*0.0254/2))/(2*PI()*($C$19*1.730734666)*$C$30)+IF($C$17="Insulated",LN((($C$13*0.0254/2)+$C$18*0.0254)/($C$13*0.0254/2))/(2*PI()*($C$20*1.730734666)*$C$30),0))) -> 0.083172283 | AA41: =IF($J41>=$C$21,0,IF($C$15="Adiabatic",0,$C$28*$AJ41*((($C$16-32)*5/9+273.15)-$O41)*(1-EXP(-$Z41/($C$28*$AJ41))))) -> 6.4655797 | AB41: =IF($J41>=$C$21,0,$AA41/$C$28) -> 4056.7809 | AC41: =IF($J41>=$C$21,0,$W41*($C$30/($C$12*0.0254))*($P41*$S41^2/2)) -> 0.0084936277 | AD41: =IF($J41>=$C$21,$N41,MAX(1000,$N41-$AC41)) -> 790828.63 | AE41: =IF($J41>=$C$21,$O41,$O42) -> 292.50021 | AF41: =IF($J41>=$C$21,$P41,$P42) -> 13.091105 | AG41: =IF($J41>=$C$21,$S41,$C$28/($AF41*$C$29)) -> 0.056235603 | AH41: =IF($J41>=$C$21,0,$C$30/AVERAGE($S41,$AG41)) -> 10.987914 | AI41: =IF($J41<=$C$21,IF($C$15="Adiabatic","",$C$16),"") -> 200 | AJ41: =IF($J41<=$C$21,'Property calculations'!BE40,"") -> 532.20059 | AK41: =IF($J41<=$C$21,'Property calculations'!BD40,"") -> -8874.2563 | AL41: =IF($J41<=$C$21,'Property calculations'!BF40,"") -> 314.46549 | AM41: =IF($J41<=$C$21,'Property calculations'!AU40,"") -> 1
J42: =J41+1 -> 4 | K42: =IF($J42<=$C$21,$J42*$C$11/$C$21,"") -> 8 | L42: =IF($J42<=$C$21,($O42-273.15)*9/5+32,"") -> 66.830386 | M42: =IF($J42<=$C$21,$N42/6894.757293168-$C$10,"") -> 99.999995 | N42: =IF($J42<=$C$21,$AD41,"") -> 790828.63 | O42: =IF(J42<=$C$21,IF(AND('Property calculations'!AU49=1,ABS('Property calculations'!BA49)<0.1),'Property calculations'!C49,NA()),"") -> 292.50021 | P42: =IF($J42<=$C$21,'Property calculations'!BC49,"") -> 13.091105 | Q42: =IF($J42<=$C$21,'Property calculations'!BG49,"") -> 2.2341496e-05 | R42: =IF($J42<=$C$21,'Property calculations'!BH49,"") -> 0.017479778 | S42: =IF($J42<=$C$21,$C$28/($P42*$C$29),"") -> 0.056235603 | T42: =IF($J42<=$C$21,$S42/$AL42,"") -> 0.0001764308 | U42: =IF($J42<=$C$21,$P42*$S42*($C$12*0.0254)/$Q42,"") -> 1730.0139 | V42: =IF($J42<=$C$21,$AJ42*$Q42/$R42,"") -> 0.67934059 | W42: =IF($J42<=$C$21,IF($U42<2300,64/$U42,0.25/(LOG10(($C$14/$C$12)/3.7+5.74/$U42^0.9)^2)),"") -> 0.036993923 | X42: =IF($J42<=$C$21,IF($U42<2300,3.66,IF($U42>=10000,0.023*$U42^0.8*$V42^IF((($C$16-32)*5/9+273.15)>$O42,0.4,0.3),3.66+($U42-2300)/(10000-2300)*(0.023*10000^0.8*$V42^IF((($C$16-32)*5/9+273.15)>$O42,0.4,0.3)-3.66))),"") -> 3.66 | Y42: =IF($J42<=$C$21,$X42*$R42/($C$12*0.0254),"") -> 1.2185484 | Z42: =IF(OR($J42>=$C$21,$C$15="Adiabatic"),0,1/(1/($Y42*2*PI()*($C$12*0.0254/2)*$C$30)+LN(($C$13*0.0254/2)/($C$12*0.0254/2))/(2*PI()*($C$19*1.730734666)*$C$30)+IF($C$17="Insulated",LN((($C$13*0.0254/2)+$C$18*0.0254)/($C$13*0.0254/2))/(2*PI()*($C$20*1.730734666)*$C$30),0))) -> 0.08439625 | AA42: =IF($J42>=$C$21,0,IF($C$15="Adiabatic",0,$C$28*$AJ42*((($C$16-32)*5/9+273.15)-$O42)*(1-EXP(-$Z42/($C$28*$AJ42))))) -> 5.9429381 | AB42: =IF($J42>=$C$21,0,$AA42/$C$28) -> 3728.8533 | AC42: =IF($J42>=$C$21,0,$W42*($C$30/($C$12*0.0254))*($P42*$S42^2/2)) -> 0.0088914003 | AD42: =IF($J42>=$C$21,$N42,MAX(1000,$N42-$AC42)) -> 790828.62 | AE42: =IF($J42>=$C$21,$O42,$O43) -> 299.51972 | AF42: =IF($J42>=$C$21,$P42,$P43) -> 12.775232 | AG42: =IF($J42>=$C$21,$S42,$C$28/($AF42*$C$29)) -> 0.05762605 | AH42: =IF($J42>=$C$21,0,$C$30/AVERAGE($S42,$AG42)) -> 10.707731 | AI42: =IF($J42<=$C$21,IF($C$15="Adiabatic","",$C$16),"") -> 200 | AJ42: =IF($J42<=$C$21,'Property calculations'!BE49,"") -> 531.50973 | AK42: =IF($J42<=$C$21,'Property calculations'!BD49,"") -> -4817.4756 | AL42: =IF($J42<=$C$21,'Property calculations'!BF49,"") -> 318.74029 | AM42: =IF($J42<=$C$21,'Property calculations'!AU49,"") -> 1
...

Sheet Fixed Orifice Calculator
B1: FIXED ORIFICE — GAS / LIQUID WATER | H1: DISCHARGE COEFFICIENT FROM REYNOLDS NUMBER | N1: LIQUID WATER — LOCAL PROPERTIES
B2: C.J.H. van den Bosch & R.A.P.M. Weterings (eds.), Methods for the Calculation of Physical Effects Due to Releases of Hazardous Materials (Liquids and Gases) (“Yellow Book”), CPR 14E, 3rd ed., 1997 — Ch. 2, Outflow and Spray Release. | H2: Wu, Burton & Schoenau (2002), sharp-edged orifice, Eq. 15. Hydraulic correlation; gas use is an unvalidated estimate. | N2: Select WATER in C5. Liquid equations use upstream properties and pressure drop. No external calls.
B3: =IF(UPPER(C5)="WATER",N16,IF('Property calculations'!AU7=0,'Property calculations'!AV7,IF(K5="Wu estimate","WARNING: Wu hydraulic Cd applied to gas; "&'Property calculations'!AV7,'Property calculations'!AV7))) -> Gas estimate within calculation range
B4: INPUTS
B5: Fluid | C5: ARGON | H5: Cd used for gas flow | K5: Manual | N5: Water temperature [C] | Q5: =IF(UPPER(C5)="WATER",ROUND((C9-32)*5/9,10),"")
B6: Upstream Gauge Pressure | C6: 15 | D6: psig | E6: =(C6+C8)*6894.757293168 -> 184090.02 | F6: Pa abs | H6: Independent Reynolds number, Re [-] | K6: 1000 | N6: Water density [kg/m3] | Q6: =IF(UPPER(C5)="WATER",IF(AND(Q5>=1,Q5<=90),(INDEX('gas properties'!AI$4:AI$93,MIN(89,MAX(1,INT(Q5))))+(Q5-MIN(89,MAX(1,INT(Q5))))*(INDEX('gas properties'!AI$4:AI$93,MIN(89,MAX(1,INT(Q5)))+1)-INDEX('gas properties'!AI$4:AI$93,MIN(89,MAX(1,INT(Q5)))))),NA()),"")
B7: Downstream / Back Pressure | C7: 0.01 | D7: psia | E7: =C7*6894.757293168 -> 68.947573 | F7: Pa abs | H7: Square root of entered Re [-] | K7: =IF(AND(ISNUMBER(K6),K6>=0),SQRT(K6),NA()) -> 31.622777 | N7: Dynamic viscosity [Pa.s] | Q7: =IF(UPPER(C5)="WATER",IF(AND(Q5>=1,Q5<=90),(INDEX('gas properties'!AJ$4:AJ$93,MIN(89,MAX(1,INT(Q5))))+(Q5-MIN(89,MAX(1,INT(Q5))))*(INDEX('gas properties'!AJ$4:AJ$93,MIN(89,MAX(1,INT(Q5)))+1)-INDEX('gas properties'!AJ$4:AJ$93,MIN(89,MAX(1,INT(Q5)))))),NA()),"")
B8: Ambient Pressure | C8: 11.7 | D8: psia | E8: =C8*6894.757293168 -> 80668.66 | F8: Pa abs | H8: Cd at entered Re [-] | K8: =IF(AND(ISNUMBER(K6),K6>=0),0.61*(1+1.07*EXP(-0.126*SQRT(K6))-2.07*EXP(-0.246*SQRT(K6))),NA()) -> 0.62161348 | N8: Vapor pressure [psia] | Q8: =IF(UPPER(C5)="WATER",IF(AND(Q5>=1,Q5<=90),(INDEX('gas properties'!AK$4:AK$93,MIN(89,MAX(1,INT(Q5))))+(Q5-MIN(89,MAX(1,INT(Q5))))*(INDEX('gas properties'!AK$4:AK$93,MIN(89,MAX(1,INT(Q5)))+1)-INDEX('gas properties'!AK$4:AK$93,MIN(89,MAX(1,INT(Q5))))))/6894.757293168,NA()),"")
B9: Upstream Temperature | C9: 70 | D9: °F | E9: =(C9-32)*5/9+273.15 -> 294.26111 | F9: K | N9: Liquid specific gravity [-] | Q9: =IF(UPPER(C5)="WATER",Q6/999.016,"")
B10: Orifice Diameter | C10: 0.25 | D10: in | E10: =C10*0.0254 -> 0.00635 | F10: m | H10: Cd = 0.61 [1 + 1.07 exp(-0.126 sqrt(Re)) - 2.07 exp(-0.246 sqrt(Re))] | N10: Device pressure recovery factor FL
B11: Manual Discharge Coefficient (Cd) | C11: 0.9 | D11: [-] | N11: Liquid critical-pressure factor FF | Q11: =IF(UPPER(C5)="WATER",0.96-0.28*SQRT(Q8*6894.757293168/22064000),"")
B12: Gas Density Method | C12: Peng-Robinson | N12: Actual pressure drop [psi] | Q12: =IF(UPPER(C5)="WATER",C17-C7,"")
H13: FLOW ESTIMATE AND SELECTED Cd | N13: Choked drop limit with FL [psi] | Q13: =IF(AND(UPPER(C5)="WATER",ISNUMBER(Q10),Q10>0,Q10<=1),Q10^2*(C17-Q11*Q8),"")
B14: RESULTS | H14: Upstream dynamic viscosity [Pa.s] | K14: =IF(UPPER(C5)="WATER",Q7,'Property calculations'!BG7) -> 2.2435561e-05 | N14: Pressure drop used [psi] | Q14: =IF(UPPER(C5)="WATER",IF(Q10="",Q12,IF(ISNUMBER(Q13),MIN(Q12,Q13),NA())),"")
B15: Input Check | C15: =IFERROR(IF(UPPER(C5)="WATER",IF(LEFT(N16,5)="BLOCK",N16,IF(OR(C6<0,C7<=0,C8<=0,C10<=0,C7>=C17,K18<=0,K18>1),"CHECK INPUTS","OK")),IF('Property calculations'!AU7=0,'Property calculations'!AV7,IFERROR(IF(OR(C6<0,C7<=0,C8<=0,C9<=-459.67,C10<=0,K18<=0,K18>1,C7>=C6+C8),"CHECK INPUTS","OK"),"CHECK INPUTS / Cd"))),"CHECK INPUTS / PROPERTIES") -> OK | H15: Mass flow at Cd = 1 [kg/s] | K15: =IF(UPPER(C5)="WATER",IF(LEFT(N16,5)="BLOCK",NA(),E22*SQRT(2*Q6*Q14*6894.757293168)),IF(AND(ISNUMBER(C6),ISNUMBER(C7),ISNUMBER(C8),ISNUMBER(C9),ISNUMBER(C10),C6>=0,C7>0,C8>0,C9>-459.67,C10>0,C7<C6+C8),E22*SQRT((2*C33/(C33-1))*E17*C36*C37^(2/C33)*(1-C37^((C33-1)/C33))),NA())) -> 0.017143881
B16: Flow Regime | C16: =IF(C15<>"OK","Unavailable",IF(UPPER(C5)="WATER",IF(Q10="","Liquid; FL unknown",IF(Q12>=Q13,"Liquid choked estimate","Liquid flow")),IF(E7<=E20,"Choked","Subcritical"))) -> Choked | H16: Re per unit Cd [-] | K16: =K15*E10/(E22*K14) -> 153217.59 | N16: =IF(UPPER(C5)="WATER",IFERROR(IF(OR(Q5<1,Q5>90),"BLOCK: water requires 1-90 C",IF(C17*6894.757293168>10000000,"BLOCK: water pressure exceeds 100 bar abs",IF(C17<=Q8,"BLOCK: upstream water not liquid",IF(C7<=Q8,"BLOCK: flashing / two-phase water unsupported",IF(Q10="","WARNING: FL missing; nominal flow only, cavitation/choking unscreened",IF(OR(NOT(ISNUMBER(Q10)),Q10<=0,Q10>1),"BLOCK: enter 0 < FL <= 1",IF(Q12>=Q13,"WARNING: liquid choked / cavitating estimate; verify device","Water estimate; cavitation can begin before choking"))))))),"BLOCK: invalid water inputs"),"Water mode inactive") -> Water mode inactive
B17: Upstream Absolute Pressure | C17: =$C$6+$C$8 -> 26.7 | D17: psia | E17: =$C$17*6894.757293168 -> 184090.02 | F17: Pa | H17: Self-consistent Wu Cd [-] | K17: =IF(AND(K20<0.000001,L126>0,L126<=1),L126,NA()) -> 0.61
B18: Actual Pressure Ratio, Pd / Pu | C18: =$E$7/$E$17 -> 0.00037453184 | D18: [-] | H18: Cd applied to mass-flow result [-] | K18: =IF(K5="Manual",IF(AND(ISNUMBER(C11),C11>0,C11<=1),C11,NA()),IF(K5="Wu estimate",K17,NA())) -> 0.9
B19: Critical Pressure Ratio, Pc / Pu | C19: =IF(UPPER(C5)="WATER","n.a.",(2/($C$33+1))^($C$33/($C$33-1))) -> 0.48624194 | D19: [-] | H19: Re at selected flow [-] | K19: =IF(ISNUMBER(C24),C24*E10/(E22*K14),NA()) -> 137895.83
B20: Critical Back Pressure | C20: =IF(UPPER(C5)="WATER","n.a.",$E$20/6894.757293168) -> 12.98266 | D20: psia | E20: =IF(UPPER(C5)="WATER","n.a.",$E$17*$C$19) -> 89512.289 | F20: Pa | H20: Wu iteration relative change [-] | K20: =ABS(L126-I126)/MAX(ABS(L126),0.000000000001) -> 0 | N20: FL is device-specific: enter manufacturer/test data when known. Blank FL gives nominal, unchoked flow and cannot screen cavitation. With FL, limit drop to FL^2(P1-FF Pv). Flashing is blocked. Density and viscosity are low-pressure estimates; pressure effects, reducers, viscous correction and cavitation onset are not modeled.
B21: Pressure Used in Flow Equation | C21: =IF(UPPER(C5)="WATER","n.a.",$E$21/6894.757293168) -> 12.98266 | D21: psia | E21: =IF(UPPER(C5)="WATER","n.a.",MAX($E$7,$E$20)) -> 89512.289 | F21: Pa
B22: Orifice Area | C22: =PI()/4*$C$10^2 -> 0.049087385 | D22: in² | E22: =PI()/4*$E$10^2 -> 3.1669217e-05 | F22: m² | H22: Applicability: thin, sharp-edged geometry. The paper does not validate this curve for compressible or choked gas flow, thick bores, rounded inlets, or arbitrary valves. Gas viscosity uses the workbook approximation.
B23: Upstream Density | C23: =$C$36 -> 3.0111505 | D23: kg/m³
B24: Mass Flow Rate | C24: =IF($C$15<>"OK","",$K$18*$K$15) -> 0.015429493 | D24: kg/s
B25: Mass Flow Rate | C25: =IF($C$24="","",$C$24*60) -> 0.9257696 | D25: kg/min | H25: Manual uses C11. Wu estimate couples Eq. 15 to the selected gas or liquid-water flow equation. The independent Re input only explores the curve. Water uses the liquid-property panel at right.
B26: Mass Flow Rate | C26: =IF($C$24="","",$C$24*3600) -> 55.546176 | D26: kg/hr | N26: Water range: 1-90 C (33.8-194 F), up to 100 bar absolute. Q = Cv sqrt(deltaP / SG) [US gpm]; orifice mass flow = Cd A sqrt(2 rho deltaP). Cd/FL must match the actual geometry.
B27: Mass Flow Rate | C27: =IF($C$24="","",$C$24*2.20462262185) -> 0.03401621 | D27: lb/s
B28: Mass Flow Rate | C28: =IF($C$24="","",$C$24*2.20462262185*60) -> 2.0409726 | D28: lb/min | H28: Source: Wu, D., Burton, R. & Schoenau, G. (2002), An Empirical Discharge Coefficient Model for Orifice Flow. International Journal of Fluid Power 3(3). Eq. 15 and Fig. 3, p. 15; Reynolds definition, Eq. 17.
B29: Mass Flow Rate | C29: =IF($C$24="","",$C$24*2.20462262185*3600) -> 122.45836 | D29: lb/hr
B31: CALCULATION DETAILS | H31: =HYPERLINK("https://doi.org/10.1080/14399776.2002.10781143","Open reference: doi.org/10.1080/14399776.2002.10781143") -> Open reference: doi.org/10.1080/14399776.2002.10781143 | N31: Sources: Swagelok Valve Sizing Technical Bulletin, liquid-flow equation; Emerson Valve Sizing, FL / FF choking limit. https://www.swagelok.com/downloads/webcatalogs/en/ms-06-84.pdf https://www.emerson.com/is/content/emerson/en/final-control/flow-controls/documents/d351798x012_02.pdf
B32: Molecular Weight | C32: =VLOOKUP(C5,'gas properties'!B3:E13,2,FALSE) -> 39.948 | D32: g/mol
B33: Isentropic Coefficient (k) | C33: =IF(UPPER(C5)="WATER","n.a.",'Property calculations'!BI7) -> 1.6730265 | D33: [-]
B34: Ideal-Gas Density | C34: =IF(UPPER(C5)="WATER","n.a.",(1/1000)*$E$17*$C$32/(8.314462618*$E$9)) -> 3.0057872 | D34: kg/m³ | H34: Fig. 3 plots sqrt(Re) from 0 to 50 (Re to 2,500). Above that plot, the equation approaches Cd = 0.61; this is extrapolation. General Eq. 4 needs geometry-specific fitted parameters; this calculator implements the published sharp-edge Eq. 15.
B35: Selected-method density | C35: =IF(UPPER(C5)="WATER",Q6,'Property calculations'!BC7) -> 3.0111505 | D35: kg/m³
B36: Density Used | C36: =C35 -> 3.0111505 | D36: kg/m³
B37: Pressure Ratio Used | C37: =IF(UPPER(C5)="WATER","n.a.",$E$21/$E$17) -> 0.48624194 | D37: [-]
B39: Fluid-specific equations. All phase and choking tests use absolute pressures.
B42: CALCULATION LOGIC & THEORY
B43: Cell-referenced explanation of the fixed-orifice gas-flow method, choking logic, property selection, and unit conversions.
B45: TOPIC | C45: CALCULATION CELL(S) | D45: LOGIC / THEORY / CONVERSION
...

Sheet Relief Valve Calculator
B1: RELIEF VALVE GAS CAPACITY
B2: API Standard 520 — gas relief sizing method
B3: ='Property calculations'!AV8&". Capacity estimate only; verify device sizing basis." -> Gas estimate within calculation range. Capacity estimate only; verify device sizing basis.
B4: INPUTS | H4: Size | I4: Area (in²)
B5: Gas | C5: ARGON | H5: D | I5: 0.11
B6: Relieving Gauge Pressure | C6: 9 | D6: psig | E6: =(C6+C8)*6.894757293168 -> 163.40575 | F6: kPa abs | H6: E | I6: 0.196
B7: Back Pressure | C7: 14.7 | D7: psia | E7: =C7*6.894757293168 -> 101.35293 | F7: kPa abs | H7: F | I7: 0.307
B8: Ambient Pressure | C8: 14.7 | D8: psia | E8: =C8*6.894757293168 -> 101.35293 | F8: kPa abs | H8: G | I8: 0.503
B9: Relieving Temperature | C9: 70 | D9: °F | E9: =(C9-32)*5/9+273.15 -> 294.26111 | F9: K | H9: H | I9: 0.785
B10: API Orifice Size | C10: Custom | H10: J | I10: 1.287
B11: Custom Effective Area | C11: 0.11 | D11: in² | H11: K | I11: 1.838
B12: Discharge Coefficient (Kd) | C12: 0.975 | D12: [-] | H12: L | I12: 2.853
B13: Back Pressure Factor (Kb) | C13: 1 | D13: [-] | H13: M | I13: 3.6
B14: Combination Factor (Kc) | C14: 1 | D14: [-] | H14: N | I14: 4.34
B15: Compressibility Method | C15: Peng-Robinson | H15: P | I15: 6.38
B16: Manual Compressibility (Z) | C16: 1 | D16: [-] | H16: Q | I16: 11.05
H17: R | I17: 16
B18: RESULTS | H18: T | I18: 26
B19: Input Check | C19: =IF('Property calculations'!AU8=0,'Property calculations'!AV8,IFERROR(IF(OR($C$6<0,$C$7<=0,$C$8<=0,$C$9<=-459.67,$C$12<=0,$C$12>1,$C$13<=0,$C$13>1,$C$14<=0,$C$14>1,AND($C$10="Custom",$C$11<=0),AND($C$15="Manual",$C$16<=0),$C$7>=$C$6+$C$8),"CHECK INPUTS","OK"),"CHECK INPUTS / PROPERTIES")) -> OK
B20: Flow Regime | C20: =IF($C$19<>"OK","—",IF($E$7/$E$6<=$C$24,"Sonic / Critical","Subcritical")) -> Subcritical
B21: Equation Used | C21: =IF($C$19<>"OK","—",IF($C$20="Sonic / Critical","Eq. 3.6","Eq. 3.8")) -> Eq. 3.8
B22: Upstream Absolute Pressure (P1) | C22: =$C$6+$C$8 -> 23.7 | D22: psia | E22: =$E$6 -> 163.40575 | F22: kPa
B23: Back Pressure Ratio (r = P2 / P1) | C23: =$E$7/$E$6 -> 0.62025316 | D23: [-]
B24: Critical Pressure Ratio | C24: =(2/($C$39+1))^($C$39/($C$39-1)) -> 0.48634282 | D24: [-]
B25: Critical Back Pressure | C25: =$E$25/6.894757293168 -> 11.526325 | D25: psia | E25: =$E$6*$C$24 -> 79.471213 | F25: kPa
B26: Selected Effective Area | C26: =IF($C$10="Custom",$C$11,VLOOKUP($C$10,$H$5:$I$18,2,FALSE)) -> 0.11 | D26: in² | E26: =$C$26*645.16 -> 70.9676 | F26: mm²
B27: Sonic Coefficient (C) | C27: =0.03948*SQRT($C$39*(2/($C$39+1))^(($C$39+1)/($C$39-1))) -> 0.028701628 | D27: [-]
B28: Subcritical Coefficient (F2) | C28: =IF($C$20="Subcritical",SQRT(($C$39/($C$39-1))*$C$23^(2/$C$39)*((1-$C$23^(($C$39-1)/$C$39))/(1-$C$23))),"—") -> 0.80397845 | D28: [-]
B29: Compressibility Used (Z) | C29: =$C$42 -> 0.99841809 | D29: [-]
B30: Relief Capacity | C30: =IF($C$19<>"OK","",IF($C$20="Sonic / Critical",$E$26*$C$27*$C$12*$C$13*$C$14*$E$6*SQRT($C$38/($E$9*$C$42)),$E$26*$C$28*$C$12*$C$14/17.9*SQRT($C$38*$E$6*($E$6-$E$7)/($E$9*$C$42)))) -> 115.39723 | D30: kg/hr
B31: Relief Capacity | C31: =IF($C$30="","",$C$30/60) -> 1.9232872 | D31: kg/min
B32: Relief Capacity | C32: =IF($C$30="","",$C$30/3600) -> 0.032054786 | D32: kg/s
B33: Relief Capacity | C33: =IF($C$30="","",$C$30*2.20462262185) -> 254.40735 | D33: lb/hr
B34: Relief Capacity | C34: =IF($C$30="","",$C$30*2.20462262185/60) -> 4.2401224 | D34: lb/min
B35: Relief Capacity | C35: =IF($C$30="","",$C$30*2.20462262185/3600) -> 0.070668707 | D35: lb/s
B37: CALCULATION DETAILS
B38: Molecular Weight | C38: =VLOOKUP($C$5,'gas properties'!$B$4:$E$13,2,FALSE) -> 39.948 | D38: g/mol
B39: Isentropic Coefficient (k) | C39: ='Property calculations'!BI8 -> 1.6723103 | D39: [-]
B40: Selected-method density | C40: ='Property calculations'!BC8 -> 2.6722856 | D40: kg/m³
B41: Calculated compressibility (Z) | C41: =IF('Property calculations'!AU8=1,'Property calculations'!AM8,NA()) -> 0.99841809 | D41: [-]
...

Sheet Cv flow rate calculator
B1: Cv VALVE FLOW — GAS / LIQUID WATER | H1: LIQUID WATER — LOCAL PROPERTIES
B2: Primary standards: ISA S75.01-1989 (sizing) and ISA S75.02-1989 (Cv test basis). Current successors: ANSI/ISA-75.01.01 / IEC 60534-2-1 and ANSI/ISA-75.02.01 / IEC 60534-2-3. | H2: Select WATER in C5. Liquid equations use upstream properties and pressure drop. No external calls.
B3: =IF(UPPER(C5)="WATER",H16,IF('Property calculations'!AU10=0,'Property calculations'!AV10,IF(OR('Property calculations'!AU9=0,'Property calculations'!AU11=0),"BLOCK: standard/reference property state outside range",'Property calculations'!AV10&". Gas Cv uses an approximate inlet-Z correction."))) -> Gas estimate within calculation range. Gas Cv uses an approximate inlet-Z correction.
B4: INPUTS
B5: Fluid | C5: ARGON | H5: Water temperature [C] | K5: =IF(UPPER(C5)="WATER",ROUND((C9-32)*5/9,10),"")
B6: Upstream Gauge Pressure | C6: 15 | D6: psig | E6: =C6+C8 -> 29.7 | F6: psia | H6: Water density [kg/m3] | K6: =IF(UPPER(C5)="WATER",IF(AND(K5>=1,K5<=90),(INDEX('gas properties'!AI$4:AI$93,MIN(89,MAX(1,INT(K5))))+(K5-MIN(89,MAX(1,INT(K5))))*(INDEX('gas properties'!AI$4:AI$93,MIN(89,MAX(1,INT(K5)))+1)-INDEX('gas properties'!AI$4:AI$93,MIN(89,MAX(1,INT(K5)))))),NA()),"")
B7: Downstream Gauge Pressure | C7: 1 | D7: psig | E7: =C7+C8 -> 15.7 | F7: psia | H7: Dynamic viscosity [Pa.s] | K7: =IF(UPPER(C5)="WATER",IF(AND(K5>=1,K5<=90),(INDEX('gas properties'!AJ$4:AJ$93,MIN(89,MAX(1,INT(K5))))+(K5-MIN(89,MAX(1,INT(K5))))*(INDEX('gas properties'!AJ$4:AJ$93,MIN(89,MAX(1,INT(K5)))+1)-INDEX('gas properties'!AJ$4:AJ$93,MIN(89,MAX(1,INT(K5)))))),NA()),"")
B8: Ambient / Atmospheric Pressure | C8: 14.7 | D8: psia | H8: Vapor pressure [psia] | K8: =IF(UPPER(C5)="WATER",IF(AND(K5>=1,K5<=90),(INDEX('gas properties'!AK$4:AK$93,MIN(89,MAX(1,INT(K5))))+(K5-MIN(89,MAX(1,INT(K5))))*(INDEX('gas properties'!AK$4:AK$93,MIN(89,MAX(1,INT(K5)))+1)-INDEX('gas properties'!AK$4:AK$93,MIN(89,MAX(1,INT(K5))))))/6894.757293168,NA()),"")
B9: Upstream Temperature | C9: 70 | D9: °F | E9: =C9+459.67 -> 529.67 | F9: °R | H9: Liquid specific gravity [-] | K9: =IF(UPPER(C5)="WATER",K6/999.016,"")
B10: Valve Flow Coefficient | C10: 0.73 | D10: Cv | H10: Device pressure recovery factor FL
B11: Reference / Normal Pressure | C11: 14.696 | D11: psia | H11: Liquid critical-pressure factor FF | K11: =IF(UPPER(C5)="WATER",0.96-0.28*SQRT(K8*6894.757293168/22064000),"")
B12: Reference / Normal Temperature | C12: 32 | D12: °F | H12: Actual pressure drop [psi] | K12: =IF(UPPER(C5)="WATER",C19-C20,"")
B13: Gas Density Method | C13: Peng-Robinson | H13: Choked drop limit with FL [psi] | K13: =IF(AND(UPPER(C5)="WATER",ISNUMBER(K10),K10>0,K10<=1),K10^2*(C19-K11*K8),"")
H14: Pressure drop used [psi] | K14: =IF(UPPER(C5)="WATER",IF(K10="",K12,IF(ISNUMBER(K13),MIN(K12,K13),NA())),"")
B15: RESULTS
B16: Input Check | C16: =IFERROR(IF(UPPER(C5)="WATER",IF(LEFT(H16,5)="BLOCK",H16,IF(OR(C19<=0,C20<=0,C19<=C20,C10<=0),"CHECK INPUTS","OK")),IF('Property calculations'!AU10=0,'Property calculations'!AV10,IF(OR('Property calculations'!AU9=0,'Property calculations'!AU11=0),"BLOCK: reference properties",IF(OR(C19<=0,C20<0,C19<=C20,C9<=-459.67,C10<=0,C11<=0,C12<=-459.67,ISNA(MATCH(C5,'gas properties'!$B$4:$B$13,0))),"CHECK INPUTS","OK")))),"CHECK INPUTS / PROPERTIES") -> OK | H16: =IF(UPPER(C5)="WATER",IFERROR(IF(OR(K5<1,K5>90),"BLOCK: water requires 1-90 C",IF(C19*6894.757293168>10000000,"BLOCK: water pressure exceeds 100 bar abs",IF(C19<=K8,"BLOCK: upstream water not liquid",IF(C20<=K8,"BLOCK: flashing / two-phase water unsupported",IF(K10="","WARNING: FL missing; nominal flow only, cavitation/choking unscreened",IF(OR(NOT(ISNUMBER(K10)),K10<=0,K10>1),"BLOCK: enter 0 < FL <= 1",IF(K12>=K13,"WARNING: liquid choked / cavitating estimate; verify device","Water estimate; cavitation can begin before choking"))))))),"BLOCK: invalid water inputs"),"Water mode inactive") -> Water mode inactive
B17: Flow Regime | C17: =IF(C16<>"OK","Unavailable",IF(UPPER(C5)="WATER",IF(K10="","Liquid; FL unknown",IF(K12>=K13,"Liquid choked estimate","Liquid flow")),IF(C20<=0.5*C19,"High pressure drop / choked","Low pressure drop"))) -> Low pressure drop
B18: Equation Used | C18: =IF(UPPER(C5)="WATER","Q = Cv sqrt(used drop / SG), US gpm",IF(C16<>"OK","—",IF(C20<=0.5*C19,"q = 0.471 N2 Cv P1 / √(Gg T1)","q = N2 Cv P1 (1-2Δp/3P1) √(Δp/(P1 Gg T1))"))&" / sqrt(Z1)") -> q = N2 Cv P1 (1-2Δp/3P1) √(Δp/(P1 Gg T1)) / sqrt(Z1)
B19: Upstream Absolute Pressure (P1) | C19: =C6+C8 -> 29.7 | D19: psia
B20: Downstream Absolute Pressure (P2) | C20: =C7+C8 -> 15.7 | D20: psia | H20: FL is device-specific: enter manufacturer/test data when known. Blank FL gives nominal, unchoked flow and cannot screen cavitation. With FL, limit drop to FL^2(P1-FF Pv). Flashing is blocked. Density and viscosity are low-pressure estimates; pressure effects, reducers, viscous correction and cavitation onset are not modeled.
B21: Pressure Drop (Δp) | C21: =C19-C20 -> 14 | D21: psi
B22: Pressure Ratio (P2 / P1) | C22: =IF(C19>0,C20/C19,"") -> 0.52861953
B23: Choke Threshold | C23: =IF(UPPER(C5)="WATER","n.a.",0.5) -> 0.5 | D23: P2 / P1
B24: Critical Downstream Gauge Pressure | C24: =IF(UPPER(C5)="WATER","n.a.",0.5*C19-C8) -> 0.15 | D24: psig
B25: =IF(UPPER(C5)="WATER","Liquid volume flow","Gas flow") -> Gas flow | C25: =IF(C16<>"OK","",IF(UPPER(C5)="WATER",C10*SQRT(K14/K9),(IF(C16<>"OK","",IF(C20<=0.5*C19,0.471*$C$39*$C$10*$C$19*SQRT(1/($C$38*$E$9)),$C$39*$C$10*$C$19*(1-2*$C$21/(3*$C$19))*SQRT($C$21/($C$19*$C$38*$E$9)))))/SQRT('Property calculations'!AM10))) -> 8.5703891 | D25: =IF(UPPER(C5)="WATER","US gpm","SCFM") -> SCFM
B26: =IF(UPPER(C5)="WATER","Liquid volume flow","Gas flow") -> Gas flow | C26: =IF(C25="","",IF(UPPER(C5)="WATER",C25*3.785411784,C25*28.316846592)) -> 242.68639 | D26: =IF(UPPER(C5)="WATER","L/min","standard L/min") -> standard L/min | H26: Water range: 1-90 C (33.8-194 F), up to 100 bar absolute. Q = Cv sqrt(deltaP / SG) [US gpm]; orifice mass flow = Cd A sqrt(2 rho deltaP). Cd/FL must match the actual geometry.
B27: =IF(UPPER(C5)="WATER","Liquid volume flow","Reference / normal gas flow") -> Reference / normal gas flow | C27: =IF(UPPER(C5)="WATER",IF(C25="","",C25*0.003785411784*60),IF(OR(C29="",C50<=0),"",C29/C50*3600)) -> 13.77699 | D27: =IF(UPPER(C5)="WATER","m3/h","Nm3/h") -> Nm3/h
B28: Actual upstream volume flow | C28: =IF(OR(C29="",C47<=0),"",C29/C47*60/0.028316846592) -> 4.3195509 | D28: ACFM
B29: Mass Flow | C29: =IF(C25="","",IF(UPPER(C5)="WATER",C25*0.003785411784/60*K6,C25*0.028316846592/60*C44)) -> 0.0068296188 | D29: kg/s
B30: Mass Flow | C30: =IF(C29="","",C29*60) -> 0.40977713 | D30: kg/min
B31: Mass Flow | C31: =IF(C29="","",C29*3600) -> 24.586628 | D31: kg/h | H31: Sources: Swagelok Valve Sizing Technical Bulletin, liquid-flow equation; Emerson Valve Sizing, FL / FF choking limit. https://www.swagelok.com/downloads/webcatalogs/en/ms-06-84.pdf https://www.emerson.com/is/content/emerson/en/final-control/flow-controls/documents/d351798x012_02.pdf
B32: Mass Flow | C32: =IF(C29="","",C29*2.20462262185) -> 0.015056732 | D32: lb/s
B33: Mass Flow | C33: =IF(C29="","",C29*2.20462262185*60) -> 0.90340392 | D33: lb/min
B34: Mass Flow | C34: =IF(C29="","",C29*2.20462262185*3600) -> 54.204235 | D34: lb/h
B36: CALCULATION DETAILS
B37: Molecular Weight | C37: =VLOOKUP(C5,'gas properties'!B3:E13,2,FALSE) -> 39.948 | D37: kg/kmol
B38: Gas Specific Gravity (air = 1) | C38: =IF(UPPER(C5)="WATER","n.a.",VLOOKUP(C5,'gas properties'!$B$4:$E$13,4,FALSE)) -> 1.3791599
B39: Gas-Flow Equation N2 Constant | C39: 22.67 | D39: SCFM / psia / °R basis
B40: SCFM Reference Pressure | C40: 14.7 | D40: psia
B41: SCFM Reference Temperature | C41: 60 | D41: °F
...

Sheet Roark Beam Table 8.1
B1: ROARK TABLE 8.1 — BEAM RESPONSE CALCULATOR
B2: Cases 1a, 1d, 1e, 2a, 2d, and 2e: reactions, end actions, and response at any position x
B3: Use consistent U.S. units shown. Loads are positive downward; deflection is positive upward per the reference sign convention.
B5: INPUTS | F5: SUPPORTED CASES
B6: Reference case | C6: 1e | D6: case | F6: Ref. | G6: Loading | H6: End restraints
B7: Case description | C7: =IF(UPPER(C6)="1A","1a — concentrated load; left free, right fixed",IF(UPPER(C6)="1D","1d — concentrated load; both ends fixed",IF(UPPER(C6)="1E","1e — concentrated load; both ends simply supported",IF(UPPER(C6)="2A","2a — partial linear distributed load; left free, right fixed",IF(UPPER(C6)="2D","2d — partial linear distributed load; both ends fixed",IF(UPPER(C6)="2E","2e — partial linear distributed load; both ends simply supported","Select a supported case")))))) -> 1e — concentrated load; both ends simply supported | F7: 1a | G7: Point load W at a | H7: Left free / right fixed
B8: Beam length, l | C8: 120 | D8: in | F8: 1d | G8: Point load W at a | H8: Fixed / fixed
B9: Load location / start, a | C9: 60 | D9: in | F9: 1e | G9: Point load W at a | H9: Simply supported / simply supported
B10: Evaluation position, x | C10: 60 | D10: in | F10: 2a | G10: Linear load from a to l | H10: Left free / right fixed
B11: Concentrated load, W | C11: 1000 | D11: lbf | F11: 2d | G11: Linear load from a to l | H11: Fixed / fixed
B12: Distributed load at a, wₐ | C12: 10 | D12: lbf/in | F12: 2e | G12: Linear load from a to l | H12: Simply supported / simply supported
B13: Distributed load at l, wₗ | C13: 10 | D13: lbf/in
B14: Elastic modulus, E | C14: 29000000 | D14: psi | F14: SECTION PROPERTIES & STRESS CHECK
B15: Area moment of inertia, I | C15: =IF($G$21="OK",$G$23,"") -> 169.76536 | D15: in⁴ | F15: Section type | G15: Solid Square Bar | I15: Common name | J15: Industry designation
B16: Input check | C16: =IF(NOT(OR(UPPER(C6)="1A",UPPER(C6)="1D",UPPER(C6)="1E",UPPER(C6)="2A",UPPER(C6)="2D",UPPER(C6)="2E")),"CHECK: choose 1a, 1d, 1e, 2a, 2d, or 2e",IF(C8<=0,"CHECK: l must be > 0",IF(OR(C9<0,C9>C8),"CHECK: a must satisfy 0 <= a <= l",IF(OR(C10<0,C10>C8),"CHECK: x must satisfy 0 <= x <= l",IF(AND(LEFT(UPPER(C6),1)="2",C9>=C8),"CHECK: distributed load requires a < l",IF(OR(C14<=0,C15<=0),"CHECK: E and I must be > 0","OK")))))) -> OK | F16: =IF($G$15="Pipe / Round HSS","Outside diameter, OD",IF($G$15="Solid Round Bar (Rod)","Diameter, d",IF($G$15="Solid Square Bar","Side, b",IF($G$15="HSS Square Tube","Outside side, B",IF($G$15="Solid Rectangular Bar","Width, b",IF($G$15="HSS Rectangular Tube","Outside width, B",IF($G$15="Wide-Flange (W-Shape) / I-Beam","Overall depth, d","Dimension 1"))))))) -> Side, b | G16: 6.718272 | H16: in | I16: Pipe | J16: Pipe / Round HSS
B17: Evaluation note | C17: =IF(AND(LEFT(UPPER(C6),1)="1",ABS(C10-C9)<0.0000000001),"At x=a, V(x) reports the right-hand shear; shear is discontinuous at the point load.","") -> At x=a, V(x) reports the right-hand shear; shear is discontinuous at the point load. | F17: =IF($G$15="Pipe / Round HSS","Wall thickness, t",IF($G$15="HSS Square Tube","Wall thickness, t",IF($G$15="Solid Rectangular Bar","Height, h",IF($G$15="HSS Rectangular Tube","Outside height, H",IF($G$15="Wide-Flange (W-Shape) / I-Beam","Flange width, bf",""))))) | H17: =IF(F17<>"","in","") | I17: Rod | J17: Solid Round Bar
F18: =IF($G$15="HSS Rectangular Tube","Wall thickness, t",IF($G$15="Wide-Flange (W-Shape) / I-Beam","Flange thickness, tf","")) | H18: =IF(F18<>"","in","") | I18: Square | J18: Solid Square Bar
B19: RESULTS | F19: =IF($G$15="Wide-Flange (W-Shape) / I-Beam","Web thickness, tw","") | H19: =IF(F19<>"","in","") | I19: Square stock (hollow) | J19: HSS Square Tube
B20: Active case | C20: =C7 -> 1e — concentrated load; both ends simply supported | F20: Max allowable stress | G20: 36000 | H20: psi | I20: Rectangle | J20: Solid Rectangular Bar
B21: Left reaction, Rₐ | C21: =IF($C$16<>"OK","",CHOOSE(MATCH(UPPER($C$6),{"1A","1D","1E","2A","2D","2E"},0),0,$C$11/$C$8^3*$C$43^2*($C$8+2*$C$9),$C$11/$C$8*$C$43,0,$C$12/(2*$C$8^3)*$C$43^3*($C$8+$C$9)+($C$13-$C$12)/(20*$C$8^3)*$C$43^3*(3*$C$8+2*$C$9),$C$12/(2*$C$8)*$C$43^2+($C$13-$C$12)/(6*$C$8)*$C$43^2)) -> 500 | D21: lbf | F21: Section input check | G21: =IF($G$15="Pipe / Round HSS",IF(AND($G$16>0,$G$17>0,2*$G$17<$G$16),"OK","CHECK: OD > 2t > 0"),IF($G$15="Solid Round Bar (Rod)",IF($G$16>0,"OK","CHECK: d must be > 0"),IF($G$15="Solid Square Bar",IF($G$16>0,"OK","CHECK: b must be > 0"),IF($G$15="HSS Square Tube",IF(AND($G$16>0,$G$17>0,2*$G$17<$G$16),"OK","CHECK: B > 2t > 0"),IF($G$15="Solid Rectangular Bar",IF(AND($G$16>0,$G$17>0),"OK","CHECK: b and h must be > 0"),IF($G$15="HSS Rectangular Tube",IF(AND($G$16>0,$G$17>0,$G$18>0,2*$G$18<MIN($G$16,$G$17)),"OK","CHECK: B,H > 2t > 0"),IF($G$15="Wide-Flange (W-Shape) / I-Beam",IF(AND($G$16>0,$G$17>0,$G$18>0,$G$19>0,2*$G$18<$G$16,$G$19<=$G$17),"OK","CHECK: d > 2tf and bf >= tw > 0"),"CHECK: choose section type"))))))) -> OK | H21: geometry | I21: Hollow rectangle | J21: HSS Rectangular Tube
B22: Right reaction, Rᵦ | C22: =IF($C$16<>"OK","",CHOOSE(MATCH(UPPER($C$6),{"1A","1D","1E","2A","2D","2E"},0),$C$11,$C$11*$C$9^2/$C$8^3*(3*$C$8-2*$C$9),$C$11*$C$9/$C$8,($C$12+$C$13)/2*$C$43,$C$48-$C$21,$C$48-$C$21)) -> 500 | D22: lbf | F22: Extreme-fiber distance, c | G22: =IF($G$21<>"OK","",IF($G$15="Pipe / Round HSS",$G$16/2,IF($G$15="Solid Round Bar (Rod)",$G$16/2,IF($G$15="Solid Square Bar",$G$16/2,IF($G$15="HSS Square Tube",$G$16/2,IF($G$15="Solid Rectangular Bar",$G$17/2,IF($G$15="HSS Rectangular Tube",$G$17/2,IF($G$15="Wide-Flange (W-Shape) / I-Beam",$G$16/2,"")))))))) -> 3.359136 | H22: in | I22: I beam | J22: Wide-Flange (W-Shape) / I-Beam
B23: Left end moment, Mₐ | C23: =IF($C$16<>"OK","",CHOOSE(MATCH(UPPER($C$6),{"1A","1D","1E","2A","2D","2E"},0),0,-$C$11*$C$9/$C$8^2*$C$43^2,0,0,-$C$12/(12*$C$8^2)*$C$43^3*($C$8+3*$C$9)-($C$13-$C$12)/(60*$C$8^2)*$C$43^3*(2*$C$8+3*$C$9),0)) -> 0 | D23: lbf·in | F23: Area moment of inertia, I | G23: =IF($G$21<>"OK","",IF($G$15="Pipe / Round HSS",PI()/64*($G$16^4-($G$16-2*$G$17)^4),IF($G$15="Solid Round Bar (Rod)",PI()*$G$16^4/64,IF($G$15="Solid Square Bar",$G$16^4/12,IF($G$15="HSS Square Tube",($G$16^4-($G$16-2*$G$17)^4)/12,IF($G$15="Solid Rectangular Bar",$G$16*$G$17^3/12,IF($G$15="HSS Rectangular Tube",($G$16*$G$17^3-($G$16-2*$G$18)*($G$17-2*$G$18)^3)/12,IF($G$15="Wide-Flange (W-Shape) / I-Beam",2*($G$17*$G$18^3/12+$G$17*$G$18*($G$16/2-$G$18/2)^2)+$G$19*($G$16-2*$G$18)^3/12,"")))))))) -> 169.76536 | H23: in^4
B24: Right end moment, Mᵦ | C24: =IF($C$16<>"OK","",CHOOSE(MATCH(UPPER($C$6),{"1A","1D","1E","2A","2D","2E"},0),-$C$11*$C$43,-$C$11*$C$9^2/$C$8^2*$C$43,0,-$C$12/2*$C$43^2-($C$13-$C$12)/6*$C$43^2,$C$21*$C$8+$C$23-$C$12/2*$C$43^2-($C$13-$C$12)/6*$C$43^2,0)) -> 0 | D24: lbf·in | F24: Section modulus, S = I/c | G24: =IF(OR($G$23="",$G$22<=0),"",$G$23/$G$22) -> 50.538401 | H24: in^3
B25: Left end slope, θₐ | C25: =IF($C$16<>"OK","",CHOOSE(MATCH(UPPER($C$6),{"1A","1D","1E","2A","2D","2E"},0),$C$11*$C$43^2/(2*$C$47),0,-$C$11*$C$9*(2*$C$8-$C$9)*$C$43/(6*$C$47*$C$8),$C$12*$C$43^3/(6*$C$47)+($C$13-$C$12)*$C$43^3/(24*$C$47),0,-$C$12*$C$43^2*($C$8^2+2*$C$9*$C$8-$C$9^2)/(24*$C$47*$C$8)-($C$13-$C$12)*$C$43^2*(7*$C$8^2+6*$C$9*$C$8-3*$C$9^2)/(360*$C$47*$C$8))) -> -0.0001828081 | D25: rad | F25: Maximum |bending moment| | G25: =IF($C$16<>"OK","",MAX(ABS($C$35),ABS($C$36))) -> 30000 | H25: lbf-in
B26: Right end slope, θᵦ | C26: =IF($C$16<>"OK","",CHOOSE(MATCH(UPPER($C$6),{"1A","1D","1E","2A","2D","2E"},0),0,0,$C$11*$C$9*($C$8^2-$C$9^2)/(6*$C$47*$C$8),0,0,$C$12*($C$8^2-$C$9^2)^2/(24*$C$47*$C$8)+($C$13-$C$12)*$C$43^2*(8*$C$8^2+9*$C$9*$C$8+3*$C$9^2)/(360*$C$47*$C$8))) -> 0.0001828081 | D26: rad | F26: Predicted max bending stress | G26: =IF(OR($G$24="",$G$24<=0,$G$25=""),"",$G$25/$G$24) -> 593.60801 | H26: psi
B27: Left end deflection, yₐ | C27: =IF($C$16<>"OK","",CHOOSE(MATCH(UPPER($C$6),{"1A","1D","1E","2A","2D","2E"},0),-$C$11*(2*$C$8^3-3*$C$8^2*$C$9+$C$9^3)/(6*$C$47),0,0,-$C$12*$C$43^3*(3*$C$8+$C$9)/(24*$C$47)-($C$13-$C$12)*$C$43^3*(4*$C$8+$C$9)/(120*$C$47),0,0)) -> 0 | D27: in | F27: Location of max stress | G27: =IF($G$26="","",IF(ABS($C$35)>=ABS($C$36),$F$35,$F$36)) -> 60 | H27: in
B28: Right end deflection, yᵦ | C28: =IF($C$16<>"OK","",0) -> 0 | D28: in | F28: Factor of safety | G28: =IF(OR($G$26="",$G$20<=0),"",$G$20/$G$26) -> 60.646081 | I28: =IF($G$28="","ENTER ALLOWABLE",IF($G$28>=1,"PASS","FAIL")) -> PASS
B29: Shear at x, V(x) | C29: =IF($C$16<>"OK","",IF($C$46="1",$C$21-$C$11*$C$45,$C$21-$C$12*$C$44-($C$13-$C$12)*$C$44^2/(2*$C$43))) -> -500 | D29: lbf | E29: at x = | F29: =$C$10 -> 60 | G29: in
B30: Moment at x, M(x) | C30: =IF($C$16<>"OK","",IF($C$46="1",$C$23+$C$21*$C$10-$C$11*$C$44,$C$23+$C$21*$C$10-$C$12*$C$44^2/2-($C$13-$C$12)*$C$44^3/(6*$C$43))) -> 30000 | D30: lbf·in
B31: Slope at x, θ(x) | C31: =IF($C$16<>"OK","",IF($C$46="1",$C$25+$C$23*$C$10/$C$47+$C$21*$C$10^2/(2*$C$47)-$C$11*$C$44^2/(2*$C$47),$C$25+$C$23*$C$10/$C$47+$C$21*$C$10^2/(2*$C$47)-$C$12*$C$44^3/(6*$C$47)-($C$13-$C$12)*$C$44^4/(24*$C$47*$C$43))) -> 2.7105054e-20 | D31: rad
